<mujoco model="Open_Duck_Mini_Simplified">
    <compiler angle="radian" />
    <asset>
        <mesh name="Base_Link" file="meshes/Base_Link.stl" scale="0.001 0.001 0.001" />
        <mesh name="L_Thigh" file="meshes/L_Thigh.stl" scale="0.001 0.001 0.001" />
        <mesh name="L_Feet" file="meshes/L_Feet.stl" scale="0.001 0.001 0.001" />
        <mesh name="L_Shin" file="meshes/L_Shin.stl" scale="0.001 0.001 0.001" />
        <mesh name="L_hip_Roll2Pitch" file="meshes/L_hip_Roll2Pitch.stl" scale="0.001 0.001 0.001" />
        <mesh name="R_Thigh" file="meshes/R_Thigh.stl" scale="0.001 0.001 0.001" />
        <mesh name="R_hip_Roll2Pitch" file="meshes/R_hip_Roll2Pitch.stl" scale="0.001 0.001 0.001" />
        <mesh name="R_Shin" file="meshes/R_Shin.stl" scale="0.001 0.001 0.001" />
        <mesh name="L_hip_roll" file="meshes/L_hip_roll.stl" scale="0.001 0.001 0.001" />
        <mesh name="R_Feet" file="meshes/R_Feet.stl" scale="0.001 0.001 0.001" />
        <mesh name="R_hip_roll" file="meshes/R_hip_roll.stl" scale="0.001 0.001 0.001" />
    </asset>
    <worldbody>
        <light directional="true" pos="-0.5 0.5 3" dir="0 0 -1" />
        <geom pos="0 0 0" size="1 1 1" type="plane" rgba="1 0.83 0.61 0.5" />
        <body name="Base_Link" pos="0.0 0.0 0.0" euler="-0.0 0.0 -0.0">
            <geom name="Base_Link_geom" type="mesh" mesh="Base_Link" pos="0 0 0" euler="0 0 0" />
            <inertial mass="5.723028695509159" pos="-0.03415259541905878 -2.340412795917269e-05 0.033010995393600875" fullinertia="0.014888935034579219 0.029775375430773104 0.024596856798787592 -1.31497081679148e-05 0.0010673555300062514 8.067459678153918e-06" />
            <body name="L_hip_roll" pos="2.997602166487923e-16 -8.881784197001253e-18 -0.00020000000000120366" euler="-0.0 0.0 -0.0">
                <joint name="Base_Link_Revolute-1" type="hinge" axis="0.0 0.0 1.0" pos="-0.019000000000000298 0.03500000000000001 -0.013183999999998796" />
                <geom name="L_hip_roll_geom" type="mesh" mesh="L_hip_roll" pos="0 0 0" euler="0 0 0" />
                <inertial mass="0.4339278421738745" pos="-0.018876389938795472 0.03499999064295626 0.014424147719492868" fullinertia="0.00016304173334779877 0.00017625043694999206 6.796833198107345e-05 -4.4772468393329545e-11 -1.443603124298801e-07 7.70432665689498e-11" />
                <body name="L_hip_Roll2Pitch" pos="-2.997602166487923e-16 8.881784197001253e-18 0.00020000000000120366" euler="-0.0 0.0 -0.0">
                    <joint name="L_hip_roll_Revolute-4" type="hinge" axis="-1.0 0.0 0.0" pos="-0.0368 0.035 -7.4e-05" />
                    <geom name="L_hip_Roll2Pitch_geom" type="mesh" mesh="L_hip_Roll2Pitch" pos="0 0 0" euler="0 0 0" />
                    <inertial mass="0.3082636162105651" pos="-0.014818719999186636 0.0756677337249489 0.0011484913220371664" fullinertia="0.00015766967589770937 0.00010790193000719534 0.00021464794713418477 -1.2079520871565352e-05 8.001198136774002e-07 -5.182344894488114e-06" />
                    <body name="L_Thigh" pos="-0.0038000000000000347 5.329070518200751e-17 -1.35229501208034e-14" euler="1.8915628313209683e-13 0.0 -4.433649260499873e-39">
                        <joint name="L_hip_Roll2Pitch_Revolute-5" type="hinge" axis="0.0 1.0 -1.8915628313209683e-13" pos="-0.03125999999999997 0.07204999999999993 -7.400000000010575e-05" />
                        <geom name="L_Thigh_geom" type="mesh" mesh="L_Thigh" pos="0 0 0" euler="0 0 0" />
                        <inertial mass="0.7541160723872383" pos="-0.031032448659312515 0.1035388204097626 -0.021371552287224056" fullinertia="0.0012625502396723786 0.0014605185545037817 0.0006311400553176275 -2.4065390826819225e-05 -0.00020971656030293467 -4.5061987948887407e-05" />
                        <body name="L_Shin" pos="7.989164885202627e-15 0.0002499999999993019 -1.183742391143306e-14" euler="1.1636102701298318e-13 5.159039813671188e-52 2.2063555860711807e-38">
                            <joint name="L_Thigh_Revolute-8" type="hinge" axis="0.0 1.0 -3.0551731014508e-13" pos="-0.03506000000000795 0.0720499999999777 -0.0750739999999967" />
                            <geom name="L_Shin_geom" type="mesh" mesh="L_Shin" pos="0 0 0" euler="0 0 0" />
                            <inertial mass="0.2557467868050863" pos="-0.035062747188262 0.0903855262511664 -0.11582420003230887" fullinertia="0.00023075249154947026 0.00017951859009130425 8.933073588270678e-05 2.5306244335633235e-08 3.3408604775201745e-08 -5.9105960111248305e-06" />
                            <body name="L_Feet" pos="8.024692021990632e-15 4.99999999892431e-05 -1.3089262203489816e-14" euler="1.1635137298073584e-13 -2.0512638384567958e-51 1.6029359342526113e-38">
                                <joint name="L_Shin_Revolute-10" type="hinge" axis="0.0 1.0 -4.2186868312581586e-13" pos="-0.03506000000001598 0.07224999999994501 -0.1573739999999921" />
                                <geom name="L_Feet_geom" type="mesh" mesh="L_Feet" pos="0 0 0" euler="0 0 0" />
                                <inertial mass="0.7800992272550799" pos="-0.024065628437512216 0.0908422823263262 -0.18097719336339996" fullinertia="0.00021801165119084143 0.0006436064670465053 0.0007252633942760479 -5.989815767144805e-07 1.8626540982205353e-05 2.135016970591684e-06" />
                            </body>
                        </body>
                    </body>
                </body>
            </body>
            <body name="R_hip_roll" pos="2.997602166487923e-16 0.0 -0.00020000000000120366" euler="-0.0 0.0 -0.0">
                <joint name="Base_Link_Revolute-2" type="hinge" axis="0.0 0.0 1.0" pos="-0.019000000000000298 -0.035 -0.013183999999998796" />
                <geom name="R_hip_roll_geom" type="mesh" mesh="R_hip_roll" pos="0 0 0" euler="0 0 0" />
                <inertial mass="0.4339278433919401" pos="-0.018876389988406708 -0.034999973867759014 0.01442414774490302" fullinertia="0.000163041733519329 0.00017625043746260534 6.79683324017209e-05 1.640636146903185e-10 -1.4436011519614413e-07 -8.956385934007043e-11" />
                <body name="R_hip_Roll2Pitch" pos="-2.997602166487923e-16 0.0 0.00020000000000120366" euler="-0.0 0.0 -0.0">
                    <joint name="R_hip_roll_Revolute-3" type="hinge" axis="-1.0 0.0 0.0" pos="-0.0368 -0.035 -7.4e-05" />
                    <geom name="R_hip_Roll2Pitch_geom" type="mesh" mesh="R_hip_Roll2Pitch" pos="0 0 0" euler="0 0 0" />
                    <inertial mass="0.30826361621058485" pos="-0.014818719999185883 -0.07566773372495088 0.0011484913220383955" fullinertia="0.00015766967589771956 0.00010790193000720931 0.00021464794713423442 1.2079520871574189e-05 8.001198136688214e-07 5.182344894498322e-06" />
                    <body name="R_Thigh" pos="0.0 0.0 0.0" euler="-0.0 0.0 -0.0">
                        <joint name="R_hip_Roll2Pitch_Revolute-6" type="hinge" axis="0.0 1.0 0.0" pos="-0.03506 -0.07205 -7.4e-05" />
                        <geom name="R_Thigh_geom" type="mesh" mesh="R_Thigh" pos="0 0 0" euler="0 0 0" />
                        <inertial mass="0.7541160723866074" pos="-0.031032448659315325 -0.10353882040975323 -0.02137155228720713" fullinertia="0.0012625502396698997 0.0014605185545033855 0.000631140055314245 2.4065390826793e-05 -0.0002097165603029712 4.5061987949027594e-05" />
                        <body name="R_Shin" pos="7.989164885202627e-15 -0.000249999999999293 -1.183941833460267e-14" euler="-1.1636102701298318e-13 0.0 -2.5573693711075005e-39">
                            <joint name="R_Thigh_Revolute-7" type="hinge" axis="0.0 1.0 1.1636102701298318e-13" pos="-0.03506000000000799 -0.07204999999999198 -0.07507399999999655" />
                            <geom name="R_Shin_geom" type="mesh" mesh="R_Shin" pos="0 0 0" euler="0 0 0" />
                            <inertial mass="0.2557467868049433" pos="-0.03506274718826922 -0.09038552625115734 -0.1158242000323041" fullinertia="0.0002307524915494373 0.0001795185900912766 8.933073588265338e-05 -2.530624436208145e-08 3.340860476393083e-08 5.9105960111849656e-06" />
                            <body name="R_Feet" pos="8.024692021990632e-15 -4.9999999989251974e-05 -1.3017631899956232e-14" euler="-1.1635137298073587e-13 -2.975534375472387e-52 -7.684733088639688e-39">
                                <joint name="R_Shin_Revolute-9" type="hinge" axis="0.0 1.0 2.3271239999371905e-13" pos="-0.035060000000016016 -0.07224999999997483 -0.157373999999992" />
                                <geom name="R_Feet_geom" type="mesh" mesh="R_Feet" pos="0 0 0" euler="0 0 0" />
                                <inertial mass="0.7800992272563959" pos="-0.02406562843767208 -0.09084228232630734 -0.1809771933634124" fullinertia="0.0002180116512173827 0.0006436064670496896 0.0007252633942795292 5.989815788751325e-07 1.8626540981215144e-05 -2.1350169704999098e-06" />
                            </body>
                        </body>
                    </body>
                </body>
            </body>
        </body>
    </worldbody>
</mujoco>