<mujoco model="Open_Duck_Mini_Simplified">
    <compiler angle="radian" />
    <asset>
        <mesh name="Base_Link" file="meshes/Base_Link.stl" scale="0.001 0.001 0.001" />
        <mesh name="L_Thigh" file="meshes/L_Thigh.stl" scale="0.001 0.001 0.001" />
        <mesh name="L_Feet" file="meshes/L_Feet.stl" scale="0.001 0.001 0.001" />
        <mesh name="L_Shin" file="meshes/L_Shin.stl" scale="0.001 0.001 0.001" />
        <mesh name="L_hip_Roll2Pitch" file="meshes/L_hip_Roll2Pitch.stl" scale="0.001 0.001 0.001" />
        <mesh name="R_Thigh" file="meshes/R_Thigh.stl" scale="0.001 0.001 0.001" />
        <mesh name="R_hip_Roll2Pitch" file="meshes/R_hip_Roll2Pitch.stl" scale="0.001 0.001 0.001" />
        <mesh name="R_Shin" file="meshes/R_Shin.stl" scale="0.001 0.001 0.001" />
        <mesh name="L_hip_roll" file="meshes/L_hip_roll.stl" scale="0.001 0.001 0.001" />
        <mesh name="R_Feet" file="meshes/R_Feet.stl" scale="0.001 0.001 0.001" />
        <mesh name="R_hip_roll" file="meshes/R_hip_roll.stl" scale="0.001 0.001 0.001" />
    </asset>
    <worldbody>
        <light directional="true" pos="-0.5 0.5 3" dir="0 0 -1" />
        <geom pos="0 0 0" size="1 1 1" type="plane" rgba="1 0.83 0.61 0.5" />
        <body name="Base_Link" pos="0.0 0.0 0.0" euler="-0.0 0.0 -0.0">
            <geom name="Base_Link_geom" type="mesh" mesh="Base_Link" pos="0 0 0" euler="0 0 0" />
            <inertial mass="1.9684302519585641" pos="-0.03415259541905878 -2.340412795917269e-05 0.033010995393600875" fullinertia="0.005121034980046357 0.010241211931603489 0.008460065395761338 -4.522829560938849e-06 0.0003671159147792206 2.7747950485370167e-06" />
            <body name="L_hip_roll" pos="2.997602166487923e-16 -8.881784197001253e-18 -0.00020000000000120366" euler="-0.0 0.0 -0.0">
                <joint name="Base_Link_Revolute-1" type="hinge" axis="0.0 0.0 1.0" pos="-0.019000000000000298 0.03500000000000001 -0.013183999999998796" />
                <geom name="L_hip_roll_geom" type="mesh" mesh="L_hip_roll" pos="0 0 0" euler="0 0 0" />
                <inertial mass="0.1492490667349632" pos="-0.018876389938795472 0.03499999064295626 0.014424147719492868" fullinertia="5.607804841261871e-05 6.0621169396812564e-05 2.33776428469934e-05 -1.5399447721772125e-11 -4.965259153638467e-08 2.6498957935165886e-11" />
                <body name="L_hip_Roll2Pitch" pos="-2.997602166487923e-16 8.881784197001253e-18 0.00020000000000120366" euler="-0.0 0.0 -0.0">
                    <joint name="L_hip_roll_Revolute-4" type="hinge" axis="-1.0 0.0 0.0" pos="-0.0368 0.035 -7.4e-05" />
                    <geom name="L_hip_Roll2Pitch_geom" type="mesh" mesh="L_hip_Roll2Pitch" pos="0 0 0" euler="0 0 0" />
                    <inertial mass="0.10602697627624531" pos="-0.014818719999186636 0.07566773372494888 0.0011484913220371664" fullinertia="5.423033438519949e-05 3.7112765734958914e-05 7.38279563391466e-05 -4.154739662831365e-06 2.752004454686599e-07 -1.7824625751742564e-06" />
                    <body name="L_Thigh" pos="-0.0038000000000000347 5.329070518200751e-17 -1.35229501208034e-14" euler="1.8915628313209683e-13 0.0 -4.433649260499873e-39">
                        <joint name="L_hip_Roll2Pitch_Revolute-5" type="hinge" axis="0.0 1.0 -1.8915628313209683e-13" pos="-0.03125999999999997 0.07204999999999993 -7.400000000010575e-05" />
                        <geom name="L_Thigh_geom" type="mesh" mesh="L_Thigh" pos="0 0 0" euler="0 0 0" />
                        <inertial mass="0.25937750260452785" pos="-0.031032448659312515 0.1035388204097626 -0.021371552287224056" fullinertia="0.0004342529486771238 0.0005023439614216825 0.00021708001902644397 -8.27726818247285e-06 -7.213181055005393e-05 -1.5499027702165054e-05" />
                        <body name="L_Shin" pos="7.989164885202627e-15 0.0002499999999993019 -1.183742391143306e-14" euler="1.1636102701298318e-13 5.159039813671188e-52 2.2063555860711807e-38">
                            <joint name="L_Thigh_Revolute-8" type="hinge" axis="0.0 1.0 -3.0551731014508e-13" pos="-0.03506000000000795 0.0720499999999777 -0.0750739999999967" />
                            <geom name="L_Shin_geom" type="mesh" mesh="L_Shin" pos="0 0 0" euler="0 0 0" />
                            <inertial mass="0.0879638629775456" pos="-0.035062747188262 0.0903855262511664 -0.11582420003230887" fullinertia="7.936709900427646e-05 6.174524754732795e-05 3.072522125902017e-05 8.704058561309926e-09 1.1490857693420855e-08 -2.0329438509603343e-06" />
                            <body name="L_Feet" pos="8.024692021990632e-15 4.99999999892431e-05 -1.3089262203489816e-14" euler="1.1635137298073584e-13 -2.0512638384567958e-51 1.6029359342526113e-38">
                                <joint name="L_Shin_Revolute-10" type="hinge" axis="0.0 1.0 -4.2186868312581586e-13" pos="-0.03506000000001598 0.07224999999994501 -0.1573739999999921" />
                                <geom name="L_Feet_geom" type="mesh" mesh="L_Feet" pos="0 0 0" euler="0 0 0" />
                                <inertial mass="0.26831438389665163" pos="-0.024065628437512216 0.0908422823263262 -0.18097719336339996" fullinertia="7.498489913570529e-05 0.000221367829430008 0.00024945365153443747 -2.0601914103554346e-07 6.406580974771667e-06 7.343370472097901e-07" />
                            </body>
                        </body>
                    </body>
                </body>
            </body>
            <body name="R_hip_roll" pos="2.997602166487923e-16 0.0 -0.00020000000000120366" euler="-0.0 0.0 -0.0">
                <joint name="Base_Link_Revolute-2" type="hinge" axis="0.0 0.0 1.0" pos="-0.019000000000000298 -0.035 -0.013183999999998796" />
                <geom name="R_hip_roll_geom" type="mesh" mesh="R_hip_roll" pos="0 0 0" euler="0 0 0" />
                <inertial mass="0.1492490671539157" pos="-0.018876389988406708 -0.034999973867759014 0.01442414774490302" fullinertia="5.607804847161633e-05 6.06211695731254e-05 2.337764299167476e-05 5.642952350239181e-11 -4.9652523698044476e-08 -3.080540382787052e-11" />
                <body name="R_hip_Roll2Pitch" pos="-2.997602166487923e-16 0.0 0.00020000000000120366" euler="-0.0 0.0 -0.0">
                    <joint name="R_hip_roll_Revolute-3" type="hinge" axis="-1.0 0.0 0.0" pos="-0.0368 -0.035 -7.4e-05" />
                    <geom name="R_hip_Roll2Pitch_geom" type="mesh" mesh="R_hip_Roll2Pitch" pos="0 0 0" euler="0 0 0" />
                    <inertial mass="0.1060269762762521" pos="-0.014818719999185883 -0.07566773372495088 0.0011484913220383955" fullinertia="5.423033438520307e-05 3.7112765734963725e-05 7.382795633916351e-05 4.154739662834441e-06 2.7520044546570946e-07 1.7824625751777682e-06" />
                    <body name="R_Thigh" pos="0.0 0.0 0.0" euler="-0.0 0.0 -0.0">
                        <joint name="R_hip_Roll2Pitch_Revolute-6" type="hinge" axis="0.0 1.0 0.0" pos="-0.03506 -0.07205 -7.4e-05" />
                        <geom name="R_Thigh_geom" type="mesh" mesh="R_Thigh" pos="0 0 0" euler="0 0 0" />
                        <inertial mass="0.2593775026043108" pos="-0.031032448659315325 -0.10353882040975323 -0.02137155228720713" fullinertia="0.00043425294867627164 0.0005023439614215467 0.0002170800190252815 8.277268182463869e-06 -7.213181055006651e-05 1.5499027702213226e-05" />
                        <body name="R_Shin" pos="7.989164885202627e-15 -0.000249999999999293 -1.183941833460267e-14" euler="-1.1636102701298318e-13 0.0 -2.5573693711075005e-39">
                            <joint name="R_Thigh_Revolute-7" type="hinge" axis="0.0 1.0 1.1636102701298318e-13" pos="-0.03506000000000799 -0.07204999999999198 -0.07507399999999655" />
                            <geom name="R_Shin_geom" type="mesh" mesh="R_Shin" pos="0 0 0" euler="0 0 0" />
                            <inertial mass="0.08796386297749642" pos="-0.03506274718826922 -0.09038552625115734 -0.11582420003230408" fullinertia="7.936709900426562e-05 6.174524754731767e-05 3.072522125900183e-05 -8.70405857041505e-09 1.1490857689465163e-08 2.0329438509808126e-06" />
                            <body name="R_Feet" pos="8.024692021990632e-15 -4.9999999989251974e-05 -1.3017631899956232e-14" euler="-1.1635137298073587e-13 -2.975534375472387e-52 -7.684733088639688e-39">
                                <joint name="R_Shin_Revolute-9" type="hinge" axis="0.0 1.0 2.3271239999371905e-13" pos="-0.035060000000016016 -0.07224999999997483 -0.157373999999992" />
                                <geom name="R_Feet_geom" type="mesh" mesh="R_Feet" pos="0 0 0" euler="0 0 0" />
                                <inertial mass="0.2683143838971043" pos="-0.02406562843767208 -0.09084228232630734 -0.1809771933634124" fullinertia="7.49848991448334e-05 0.00022136782943110408 0.00024945365153563475 2.0601914177867484e-07 6.406580974430755e-06 -7.343370471775893e-07" />
                            </body>
                        </body>
                    </body>
                </body>
            </body>
        </body>
    </worldbody>
</mujoco>